<?xml version="1.0" ?>
<!-- =================================================================================== -->
<!-- |    This document was autogenerated by xacro from arm_hrrr.xacro                 | -->
<!-- |    EDITING THIS FILE BY HAND IS NOT RECOMMENDED                                 | -->
<!-- =================================================================================== -->
<robot name="arm_hrrr" xmlns:xacro="http://ros.org/wiki/xacro">
  <!--xacro:property name="path2Model" value="package://testbot_description/model" /-->
  <!--robot name="armHRRR"-->
  <!-- ______ links _____ -->
  <!-- ROS base_link to arm world coordinates trnsform -->
  <link name="base_link">
    <visual>
      <origin rpy="0 0 0" xyz="0 0 0.05"/>
      <geometry>
        <box size="0.1 0.1 0.1"/>
      </geometry>
      <material name="Grey"/>
    </visual>
    <collision>
      <origin rpy="0 0 0" xyz="0 0 0.05"/>
      <geometry>
        <box size="0.1 0.1 0.1"/>
      </geometry>
    </collision>
  </link>
  <link name="_L0">
    <visual>
      <origin rpy="0 0 0" xyz="0 0 0"/>
      <geometry>
        <mesh filename="package://arm_hrrr_model/meshes/L0.STL"/>
      </geometry>
      <material name="Grey"/>
    </visual>
    <collision>
      <origin rpy="0 0 0" xyz="0 0 0"/>
      <geometry>
        <mesh filename="package://arm_hrrr_model/meshes/L0.STL"/>
      </geometry>
    </collision>
    <inertial>
      <origin rpy="0 0 0" xyz="1.1345E-16 -0.013352 0.017446"/>
      <mass value="0.07757"/>
      <inertia ixx="2.6624E-05" ixy="8.3213E-21" ixz="6.6331E-21" iyy="4.1325E-05" iyz="1.2551E-06" izz="3.1336E-05"/>
    </inertial>
  </link>
  <link name="_L1">
    <visual>
      <origin rpy="0 0 0" xyz="0 0 0"/>
      <geometry>
        <mesh filename="package://arm_hrrr_model/meshes/L1.STL"/>
      </geometry>
      <material name="Grey"/>
    </visual>
    <collision>
      <origin rpy="0 0 0" xyz="0 0 0"/>
      <geometry>
        <mesh filename="package://arm_hrrr_model/meshes/L1.STL"/>
      </geometry>
    </collision>
    <inertial>
      <origin rpy="0 0 0" xyz="-0.000652188482918968 0.0205351960403008 0.0250735944101231"/>
      <mass value="0.12726"/>
      <inertia ixx="5.5052684991225E-05" ixy="-1.08478385518745E-06" ixz="1.00389750980177E-06" iyy="5.63745220297769E-05" iyz="3.00857513519924E-07" izz="5.73934780370408E-05"/>
    </inertial>
  </link>
  <link name="_L2">
    <visual>
      <origin rpy="0 0 0" xyz="0 0 0"/>
      <geometry>
        <mesh filename="package://arm_hrrr_model/meshes/L2.STL"/>
      </geometry>
      <material name="Grey"/>
    </visual>
    <collision>
      <origin rpy="0 0 0" xyz="0 0 0"/>
      <geometry>
        <mesh filename="package://arm_hrrr_model/meshes/L2.STL"/>
      </geometry>
    </collision>
    <inertial>
      <origin rpy="0 0 0" xyz="0.0711649776786391 0.00148673503523068 -0.0024225415303807"/>
      <mass value="0.0715177471991291"/>
      <inertia ixx="2.3477639305661E-05" ixy="-1.66762564977195E-06" ixz="-3.54152135672619E-06" iyy="6.64208248542604E-05" iyz="1.34881284045922E-07" izz="8.36014077475221E-05"/>
    </inertial>
  </link>
  <link name="_L3">
    <visual>
      <origin rpy="0 0 0" xyz="0 0 0"/>
      <geometry>
        <mesh filename="package://arm_hrrr_model/meshes/L3.STL"/>
      </geometry>
      <material name="Grey"/>
    </visual>
    <collision>
      <origin rpy="0 0 0" xyz="0 0 0"/>
      <geometry>
        <mesh filename="package://arm_hrrr_model/meshes/L3.STL"/>
      </geometry>
    </collision>
    <inertial>
      <origin rpy="0 0 0" xyz="0.0443605865306002 -0.00229589696194459 0.031243645036507"/>
      <mass value="0.0755630413994574"/>
      <inertia ixx="2.94318237373478E-05" ixy="3.76099873612448E-06" ixz="1.12245038462398E-05" iyy="8.53576932065445E-05" iyz="2.11221731367707E-07" izz="9.92701100131562E-05"/>
    </inertial>
  </link>
  <link name="_L4">
    <visual>
      <origin rpy="0 0 0" xyz="0 0 0"/>
      <geometry>
        <mesh filename="package://arm_hrrr_model/meshes/L4.STL"/>
      </geometry>
      <material name="Grey"/>
    </visual>
    <collision>
      <origin rpy="0 0 0" xyz="0 0 0"/>
      <geometry>
        <mesh filename="package://arm_hrrr_model/meshes/L4.STL"/>
      </geometry>
    </collision>
    <inertial>
      <origin rpy="0 0 0" xyz="0.0177621067869408 -0.00137877579388009 0"/>
      <mass value="0.0147045616164208"/>
      <inertia ixx="8.03850612396533E-06" ixy="1.23133424762755E-07" ixz="8.86897583275476E-22" iyy="2.93912182741925E-06" iyz="-1.45471455660844E-23" izz="1.01319116064202E-05"/>
    </inertial>
  </link>
  <link name="_tool">
    <inertial>
      <origin rpy="0 0 0" xyz="0.0030009631938903 -7.32426842593086E-17 -0.00531092074064319"/>
      <mass value="0.00367938214213686"/>
      <inertia ixx="1.43250300085364E-07" ixy="1.0687385703068E-22" ixz="-3.07881511704918E-08" iyy="4.48135044755976E-07" iyz="-2.89447699129957E-23" izz="4.23540638940663E-07"/>
    </inertial>
    <visual>
      <origin rpy="0 0 0" xyz="0 0 0"/>
      <geometry>
        <mesh filename="package://arm_hrrr_model/meshes/tool.STL"/>
      </geometry>
      <material name="Blue"/>
    </visual>
    <collision>
      <origin rpy="0 0 0" xyz="0 0 0"/>
      <geometry>
        <mesh filename="package://arm_hrrr_model/meshes/tool.STL"/>
      </geometry>
    </collision>
  </link>
  <link name="_endTool">
        </link>
  <!-- _____ joints _____ -->
  <joint name="_base_L0" type="fixed">
    <origin rpy="3.1416 0 0" xyz="0 0 0.1"/>
    <parent link="base_link"/>
    <child link="_L0"/>
  </joint>
  <joint name="_J0" type="revolute">
    <origin rpy="3.1416 0 0" xyz="0 0 -0.03"/>
    <parent link="_L0"/>
    <child link="_L1"/>
    <axis xyz="0 0 1"/>
    <limit effort="10" lower="-1.57" upper="1.57" velocity="4"/>
  </joint>
  <joint name="_J1" type="revolute">
    <origin rpy="1.5708 -1.5708 3.1416" xyz="0 0.0365 0.0358"/>
    <parent link="_L1"/>
    <child link="_L2"/>
    <axis xyz="0 -1 0"/>
    <limit effort="1000" lower="-0.785" upper="2.356" velocity="4"/>
  </joint>
  <joint name="_J2" type="revolute">
    <origin rpy="0 0 3.1416" xyz="0.102 0 -0.004"/>
    <parent link="_L2"/>
    <child link="_L3"/>
    <axis xyz="0 1 0"/>
    <limit effort="1000" lower="-3.14" upper="0" velocity="4"/>
  </joint>
  <joint name="_J3" type="revolute">
    <origin rpy="0 0 0" xyz="0.080 0 0.035"/>
    <parent link="_L3"/>
    <child link="_L4"/>
    <axis xyz="0 1 0"/>
    <limit effort="1000" lower="-2.356" upper="0.785" velocity="4"/>
  </joint>
  <joint name="_JTl" type="fixed">
    <origin rpy="0 0 0" xyz="0.042 0 0"/>
    <parent link="_L4"/>
    <child link="_tool"/>
  </joint>
  <joint name="_JEndTl" type="fixed">
    <origin rpy="0 0 0" xyz="0.03 0 -0.005"/>
    <parent link="_tool"/>
    <child link="_endTool"/>
  </joint>
  <material name="Green">
    <color rgba="0 0.9 0 1"/>
  </material>
  <material name="Red">
    <color rgba="0.9 0 0 1"/>
  </material>
  <material name="Blue">
    <color rgba="0 0 0.9 1"/>
  </material>
  <material name="Yellow">
    <color rgba="0.9 0.9 0 1"/>
  </material>
  <material name="Grey">
    <color rgba="0.5 0.5 0.5 1"/>
  </material>
</robot>
